---
layout: post
title: JavaScript - 예외처리
tags: JavaScript try catch finally 예외처리
description: >
  JavaScript - 예외처리
accent_image:
  background: url('/assets/img/blog/javascript_bg.jpg') center/cover
  overlay: false
sitemap: false
published: true
# invert_sidebar: true
categories:
  - 탐구생활
---

> ❗️해당 내용은 2018년 4월 15일 당시 공부한 내용을 그대로 옮겨온 글입니다.

---

### 1. JavaScript의 예외처리

```javascript
function isMan(juminNo) {
  if (juminNo.length != 13) {
    throw new Error("주민번호는 13자리 입니다.");
  }
  return true;
}

try {
  var result = isMan("123456");
} catch (e) {
  console.log("예외 발생");
  console.log(e);
}

console.log("정상 실행....");
```

입력된 juminNo의 길이가 13이 아닌 경우 에러 메세지를 발생시킵니다.<br>
function isMan의 인자값이 try문의 isMan에 선언되어있습니다.<br>
길이가 6글자이기 때문에 catch문이 발동하게 되어 "예외 발생" 이라는 메세지가 찍히고<br>
주민번호는 13자리라는 안내가 나갑니다.<br><br>

```javascript
function isMan(juminNo) {
  if (juminNo.length != 13) {
    // throw new Error("주민번호는 13자리 입니다.");
    throw { result: -1, msg: "주민번호는 13자리 입니다." };
  }
  return true;
}

try {
  var result = isMan("123456");
} catch (e) {
  console.log("예외 발생");
  console.log(e.msg);
} finally {
  console.log("항상 수행");
}

console.log("정상 실행....");
```

java처럼 try, catch와 함께 finally문을 사용할 수 있습니다.<br>
